<?xml version="1.0" ?>
<robot name="hyuspa">
   
	<link name="base_link">
		<inertial>
			<origin rpy="0.00000 -0.00000 0.00000" xyz="0.00000 0.00000 0.00000"/>
			<mass value="20.50000"/>
			<inertia ixx="0.5434" ixy="0" ixz="0" iyy="0.7492" iyz="0" izz="1.1846"/>
		</inertial>
		<visual>
			<origin rpy="0.00000 -0.00000 0.00000" xyz="0.00000 0.00000 0.00000"/>
			<geometry>
				<mesh filename="mesh/body_small.stl" scale="1.00000 1.00000 1.00000"/>
			</geometry>
		</visual>
		<collision>
			<origin rpy="0.00000 -0.00000 0.00000" xyz="0.00000 0.00000 0.00000"/>
			<geometry>
				<box size="0.550 0.50 0.150"/>
			</geometry>
		</collision>
	</link>
	<link name="left_wheel_link">
		<inertial>
			<origin rpy="0.00000 -0.00000 0.00000" xyz="0.00000 0.00000 0.00000"/>
			<mass value="1.00000"/>
			<inertia ixx="0.00000" ixy="0" ixz="0" iyy="0.00000" iyz="0" izz="0.00000"/>
		</inertial>
		<visual>
			<origin rpy="0.00000 -0.00000 0.00000" xyz="0.00000 0.00000 0.00000"/>
			<geometry>
				<mesh filename="mesh/left_wheel.stl" scale="1.00000 1.00000 1.00000"/>
			</geometry>

		</visual>
		<collision>
			<origin rpy="0.00000 -0.00000 0.00000" xyz="0.00000 0.00000 0.00000"/>
			<geometry>
                              <cylinder length="0.05" radius="0.0755"/>
			</geometry>
		</collision>
	</link>
	<link name="right_wheel_link">
		<inertial>
			<origin rpy="0.00000 -0.00000 0.00000" xyz="0.00000 0.00000 0.00000"/>
			<mass value="1.00000"/>
			<inertia ixx="0.00000" ixy="0" ixz="0" iyy="0.00000" iyz="0" izz="0.00000"/>
		</inertial>
		<visual>
			<origin rpy="0.00000 -0.00000 0.00000" xyz="0.00000 0.00000 0.00000"/>
			<geometry>
				<mesh filename="mesh/right_wheel.stl" scale="1.00000 1.00000 1.00000"/>
			</geometry>

		</visual>
		<collision>
			<origin rpy="0.00000 -0.00000 0.00000" xyz="0.00000 0.00000 0.00000"/>
			<geometry>
                              <cylinder length="0.05" radius="0.0755"/>
			</geometry>
		</collision>
	</link>
	<link name="left_front_link">
		<inertial>
			<origin rpy="0.00000 -0.00000 0.00000" xyz="0.00000 0.00000 0.00000"/>
			<mass value="1.00000"/>
			<inertia ixx="0.00000" ixy="0" ixz="0" iyy="0.00000" iyz="0" izz="0.00000"/>
		</inertial>
		<visual>
			<origin rpy="0.00000 -0.00000 0.00000" xyz="0.00000 0.00000 0.00000"/>
			<geometry>
				<mesh filename="mesh/left_front_wheel.stl" scale="1.00000 1.00000 1.00000"/>
			</geometry>
	
		</visual>
		<collision>
			<origin rpy="0.00000 -0.00000 0.00000" xyz="0.00000 0.00000 0.00000"/>
			<geometry>
                              <cylinder length="0.05" radius="0.0755"/>
			</geometry>
		</collision>
	</link>
	<link name="right_front_link">
		<inertial>
			<origin rpy="0.00000 -0.00000 0.00000" xyz="0.00000 0.00000 0.00000"/>
			<mass value="1.00000"/>
			<inertia ixx="0.00000" ixy="0" ixz="0" iyy="0.00000" iyz="0" izz="0.00000"/>
		</inertial>
		<visual>
			<origin rpy="0.00000 -0.00000 0.00000" xyz="0.00000 0.00000 0.00000"/>
			<geometry>
				<mesh filename="mesh/right_front_wheel.stl" scale="1.00000 1.00000 1.00000"/>
			</geometry>
			
		</visual>
		<collision>
			<origin rpy="0.00000 -0.00000 0.00000" xyz="0.00000 0.00000 0.00000"/>
			<geometry>
                              <cylinder length="0.05" radius="0.0755"/>
			</geometry>
		</collision>
	</link>
	<joint name="left_wheel_joint" type="continuous">
		<parent link="base_link"/>
		<child link="left_wheel_link"/>
		<dynamics damping="1.0" friction="0.01"/>
		<origin rpy="1.57000 -0.00000 0.00000" xyz="-0.20100 0.29320 -0.02000"/>
		<axis xyz="0.00000 0.00000 1.00000"/>
	</joint>
	<joint name="right_wheel_joint" type="continuous">
		<parent link="base_link"/>
		<child link="right_wheel_link"/>
		<dynamics damping="1.0" friction="0.01"/>
		<origin rpy="1.57000 -0.00000 0.00000" xyz="-0.20100 -0.29320 -0.02000"/>
		<axis xyz="0.00000 0.00000 1.00000"/>
	</joint>
	<joint name="left_front_joint" type="continuous">
		<parent link="base_link"/>
		<child link="left_front_link"/>
		<dynamics damping="1.0" friction="0.01"/>
		<origin rpy="1.57000 -0.00000 0.00000" xyz="0.20100 0.29320 -0.02000"/>
		<axis xyz="0.00000 0.00000 1.00000"/>
	</joint>
	<joint name="right_front_joint" type="continuous">
		<parent link="base_link"/>
		<child link="right_front_link"/>
		<dynamics damping="1.0" friction="0.01"/>
		<origin rpy="1.57000 -0.00000 0.00000" xyz="0.20100 -0.29320 -0.02000"/>
		<axis xyz="0.00000 0.00000 1.00000"/>
	</joint>


  <joint name="Arm_Joint_base_joint" type="fixed">
    <axis xyz="0 0 1"/>
    <parent link="base_link"/>
    <child link="SPA_Base_Link"/>
    <origin rpy="0 0 1.57" xyz="0.085 0 0.0765"/>
  </joint>

  <link name="SPA_Base_Link">
    <inertial>
      <origin rpy="0 0 0" xyz="0.0 0 0"/>
      <mass value="14.299"/>
      <inertia ixx="4.7569" ixy="3.5447e-06" ixz="1.3257e-05" iyy="4.7075" iyz="0.21788" izz="0.16593"/>
    </inertial>
    <visual>
      <origin rpy="0 0 0" xyz="0 0 0"/>
      <geometry>
        <mesh filename="mesh/SPA_Base_Link.stl" scale="1 1 1"/>
      </geometry>
    </visual>
    <collision>
      <origin rpy="0 0 0" xyz="0 0 0"/>
	   <geometry>
           <mesh filename="mesh/SPA_Base_Link.stl" scale="1 1 1"/>
	   </geometry>
		</collision>
  </link>


  <joint name="Arm_Joint_1" type="revolute">
    <axis xyz="0 0 1"/>
    <limit effort="50" lower="-3.09" upper="1.11" velocity="4"/>
    <origin rpy="0 0 0" xyz="0 0 0.1007"/>
    <!--<origin rpy="0 0 0" xyz="0 -0.3107 1.567"/>-->
    <parent link="SPA_Base_Link"/>
    <child link="SPA_Link_01"/>
    <dynamics damping="0.0" friction="0.7"/>
  </joint>

  <link name="SPA_Link_01">
    <inertial>
      <mass value="0.19005572"/>
      <origin rpy="0 0 0" xyz="0.00254562 -0.04683692 0.00039303"/>
      <inertia ixx="0.0001285" ixy="-6.96e-06" ixz="-3.3e-07" iyy="0.00013782" iyz="1.58e-06" izz="0.00017651"/>
    </inertial>
    <visual>
      <origin rpy="0 0 0" xyz="0 0 0"/>
      <geometry>
        <mesh filename="mesh/SPA_Link_01.stl" scale="1 1 1"/>
      </geometry>
    </visual>
    <collision>
      <origin rpy="0 0 0" xyz="0 0 0"/>
      <geometry>
        <mesh filename="mesh/SPA_Link_01.stl" scale="1 1 1"/>
      </geometry>
    </collision>
  </link>

  <joint name="Arm_Joint_2" type="revolute">
    <axis xyz="1 0 0"/>
    <limit effort="50" lower="-1.57" upper="1.9" velocity="4"/>
    <origin rpy="0 0 0" xyz="0  0 0.054"/>
    <parent link="SPA_Link_01"/>
    <child link="SPA_Link_02"/>
  </joint>

  <link name="SPA_Link_02">
    <inertial>
      <mass value="0.23507347"/>
      <origin rpy="0 0 0" xyz="0.00092832 -0.00216813 -0.08253839"/>
      <inertia ixx="0.00070279" ixy="1.89e-06" ixz="2.918e-05" iyy="0.00075402" iyz="-1.867e-05" izz="0.00018758"/>
    </inertial>
    <visual>
      <origin rpy="0 0 0" xyz="0 0 0"/>
      <geometry>
        <mesh filename="mesh/SPA_Link_02.stl" scale="1 1 1"/>
      </geometry>
    </visual>
        <collision>
			<origin rpy="0.00000 -0.00000 0.00000" xyz="0.00000 0.00000 0.00000"/>
			<geometry>
              <mesh filename="mesh/SPA_Link_02.stl" scale="1 1 1"/>
			</geometry>
		</collision>
  </link>


  <joint name="Arm_Joint_3" type="revolute">
    <axis xyz="0 0 1"/>
    <limit effort="50" lower="-1.09" upper="1.34" velocity="4"/>
    <origin rpy="0 0 0" xyz="0  0 0.1458"/>
    <parent link="SPA_Link_02"/>
    <child link="SPA_Link_03"/>
    <dynamics damping="0.0" friction="0.7"/>
  </joint>

  <link name="SPA_Link_03">
    <inertial>
      <mass value="0.23988959"/>
      <origin rpy="0 0 0" xyz="-0.00091617 0.00049181 -0.11495311"/>
      <inertia ixx="0.00078386" ixy="-1.09e-06" ixz="-1.183e-05" iyy="0.00076388" iyz="2.7e-07" izz="0.00015303"/>
    </inertial>
    <visual>
      <origin rpy="0 0 0" xyz="0 0 0"/>
      <geometry>
        <mesh filename="mesh/SPA_Link_03.stl" scale="1 1 1"/>
      </geometry>
    </visual>
  <collision>
			<origin rpy="0.00000 -0.00000 0.00000" xyz="0.00000 0.00000 0.00000"/>
			<geometry>
        <mesh filename="mesh/SPA_Link_03.stl" scale="1 1 1"/>
			</geometry>
		</collision>


  </link>


  <joint name="Arm_Joint_4" type="revolute">
    <axis xyz="0 1 0"/>
    <limit effort="50" lower="-2.48" upper="0.156" velocity="4"/>
    <origin rpy="0 0 0" xyz="0 0 0.1542 "/>
    <parent link="SPA_Link_03"/>
    <child link="SPA_Link_04"/>
    <dynamics damping="0.0" friction="0.7"/>
  </joint>
  
  <link name="SPA_Link_04">
    <inertial>
      <mass value="0.21818283"/>
      <origin rpy="0 0 0" xyz="-0.00205573 -0.00034472 -0.08047106"/>
      <inertia ixx="0.00060829" ixy="-8.2e-07" ixz="-1.431e-05" iyy="0.00057822" iyz="-1.577e-05" izz="0.00015487"/>
    </inertial>
    <visual>
      <origin rpy="0 0 0" xyz="0 0 0"/>
      <geometry>
        <mesh filename="mesh/SPA_Link_04.stl" scale="1 1 1"/>
      </geometry>
    </visual>
  <collision>
			<origin rpy="0.00000 -0.00000 0.00000" xyz="0.00000 0.00000 0.00000"/>
			<geometry>
        <mesh filename="mesh/SPA_Link_04.stl" scale="1 1 1"/>
			</geometry>
		</collision>


  </link>
  <joint name="Arm_Joint_5" type="revolute">
    <axis xyz="0 0 1"/>
    <limit effort="50" lower="-3.14" upper="3.14" velocity="4"/>
    <origin rpy="0 0 0" xyz="0 0 0.1458 "/>
    <parent link="SPA_Link_04"/>
    <child link="SPA_Link_05"/>
    <dynamics damping="0.0" friction="0.7"/>
  </joint>
 
  <link name="SPA_Link_05">
    <inertial>
      <mass value="0.23921278"/>
      <origin rpy="0 0 0" xyz="0.00001947 -0.00083897 -0.11413674"/>
      <inertia ixx="0.00078209" ixy="1.23e-06" ixz="1.6e-06" iyy="0.00079802" iyz="-9.53e-06" izz="0.0001501"/>
    </inertial>
    <visual>
      <origin rpy="0 0 0" xyz="0 0 0"/>
      <geometry>
        <mesh filename="mesh/SPA_Link_05.stl" scale="1 1 1"/>
      </geometry>
    </visual>
  <collision>
			<origin rpy="0.00000 -0.00000 0.00000" xyz="0.00000 0.00000 0.00000"/>
			<geometry>
        <mesh filename="mesh/SPA_Link_05.stl" scale="1 1 1"/>
			</geometry>
		</collision>



  </link>
  <joint name="Arm_Joint_6" type="revolute">
    <axis xyz="1 0 0"/>
    <limit effort="50" lower="-1.41" upper="1.392" velocity="4"/>
    <origin rpy="0 0 0" xyz="0 0 0.1542 "/>
    <parent link="SPA_Link_05"/>
    <child link="SPA_Link_06"/>
    <dynamics damping="0.0" friction="0.7"/>
  </joint>

  <link name="SPA_Link_06">
    <inertial>
      <mass value="0.21223655"/>
      <origin rpy="0 0 0" xyz="-0.00927893 0.00079275 -0.01472434"/>
      <inertia ixx="0.00029546" ixy="1.33e-06" ixz="-2.465e-05" iyy="0.00035304" iyz="5e-08" izz="0.00023162"/>
    </inertial>
    <visual>
      <origin rpy="0 0 0" xyz="0 0 0"/>
      <geometry>
        <mesh filename="mesh/SPA_Link_06.stl" scale="1 1 1"/>
      </geometry>
    </visual>
  <collision>
			<origin rpy="0.00000 -0.00000 0.00000" xyz="0.00000 0.00000 0.00000"/>
			<geometry>
        <mesh filename="mesh/SPA_Link_06.stl" scale="1 1 1"/>
			</geometry>
		</collision>

  </link>

</robot>

